<?xml version="1.0"?>
<robot name="human_movable">
<!--
<link name="base_footprint"/>
-->
<link name="base_link">
  <visual>
    <geometry>
      <box size="0.4 0.42 0.1"/>
    </geometry>
  </visual>
  <collision>
    <geometry>
      <box size="0.4 0.42 0.1"/>
    </geometry>
  </collision>
  <inertial>
      <origin xyz="0.01 0 0" rpy="0 0 0"/>
      <mass value="10.0"/>
      <inertia
        ixx="0.074" ixy="0.0" ixz="0.0"
        iyy="0.12" iyz="0.0"
        izz="0.15"/>
  </inertial>
    
  <visual name='body_visual'>
  	<origin xyz="0 0 1.2" rpy="0 0 0"/>
    <geometry>
      <box size="0.2 0.5 0.6"/>
    </geometry>
  </visual>
  <collision name='body_collision'>
  	<origin xyz="0 0 1.2" rpy="0 0 0"/>
    <geometry>
      <box size="0.2 0.4 0.6"/>
    </geometry>
  </collision>
  
  <visual name='leg_visual'>
  	<origin xyz="0 0 0.45" rpy="0 0 0"/>
    <geometry>
      <box size="0.18 0.36 0.9"/>
    </geometry>
  </visual>
  <collision name='leg_collision'>
  	<origin xyz="0 0 0.45" rpy="0 0 0"/>
    <geometry>
      <box size="0.18 0.36 0.9"/>
    </geometry>
  </collision>
  
  <visual name='head_visual'>
  	<origin xyz="0 0 1.65" rpy="0 0 0"/>
    <geometry>
      <sphere radius="0.15"/>
    </geometry>
  </visual>
  <collision name='head_collision'>
  	<origin xyz="0 0 1.65" rpy="0 0 0"/>
    <geometry>
      <sphere radius="0.15"/>
    </geometry>
  </collision>
  
</link>

<gazebo reference="base_link">
  <material value="Gazebo/Yellow"/>
</gazebo>

<link name="left_wheel_link">
  <visual>
    <geometry>
      <cylinder length="0.04" radius="0.1"/>
    </geometry>
    <origin xyz="0 0 0" rpy="1.57075 0 0"/>
    <material name="blue">
      <color rgba="0 0 .8 1"/>
    </material>
  </visual>
  <collision>
    <geometry>
      <cylinder length="0.04" radius="0.1"/>
    </geometry>
    <origin xyz="0 0 0" rpy="1.57075 0 0"/>
  </collision>
  <inertial>
      <origin xyz="0 0 0" rpy="0 0 0"/>
      <mass value="0.01"/>
      <inertia
        ixx="0.01" ixy="0.0" ixz="0.0"
        iyy="0.01" iyz="0.0"
        izz="0.01"/>
    </inertial>
</link>

<gazebo reference="left_wheel_link">
  <mu1>1.0</mu1>
  <mu2>1.0</mu2>
  <kp>1000000.0</kp> 
  <kd>100.0</kd>
  <minDepth>0.001</minDepth>
  <maxVel>1.0</maxVel>
</gazebo>

<joint name="base_to_left_wheel" type="continuous">
  <parent link="base_link"/>
  <child link="right_wheel_link"/>
  <origin xyz="0 -0.23 0" rpy="0 0 0"/>
  <axis xyz="0 1 0"/>
</joint>

<link name="right_wheel_link">
  <visual>
    <geometry>
      <cylinder length="0.04" radius="0.1"/>
    </geometry>
    <origin xyz="0 0 0" rpy="1.57075 0 0"/>
    <material name="blue"/>
  </visual>
  <collision>
    <geometry>
      <cylinder length="0.04" radius="0.1"/>
    </geometry>
    <origin xyz="0 0 0" rpy="1.57075 0 0"/>
  </collision>
  <inertial>
      <origin xyz="0 0 0" rpy="0 0 0"/>
      <mass value="0.01"/>
      <inertia
        ixx="0.01" ixy="0.0" ixz="0.0"
        iyy="0.01" iyz="0.0"
        izz="0.01"/>
    </inertial>
</link>
<gazebo reference="right_wheel_link">
  <mu1>1.0</mu1>
  <mu2>1.0</mu2>
  <kp>1000000.0</kp>
  <kd>100.0</kd>
  <minDepth>0.001</minDepth>
  <maxVel>1.0</maxVel>
</gazebo>


<joint name="base_to_right_wheel" type="continuous">
  <parent link="base_link"/>
  <child link="left_wheel_link"/>
  <origin xyz="0 0.23 0" rpy="0 0 0"/>
  <axis xyz="0 1 0"/>
</joint>

<link name="front_wheel_link">
  <visual>
    <geometry>
      <sphere radius="0.009"/>
    </geometry>
    <origin xyz="0 0 0" rpy="0 0 0"/>
    <material name="blue"/>
  </visual>
  <collision>
    <geometry>
      <sphere radius="0.009"/>
    </geometry>
    <origin xyz="0 0 0" rpy="1.0 0 0"/>
  </collision>
  <inertial>
      <origin xyz="0 0 0" rpy="0 0 0"/>
      <mass value="0.01"/>
      <inertia
        ixx="0.01" ixy="0.0" ixz="0.0"
        iyy="0.01" iyz="0.0"
        izz="0.01"/>
    </inertial>
</link>

<joint name="base_to_front_wheel" type="fixed">
  <parent link="base_link"/>
  <child link="front_wheel_link"/>
  <origin xyz="0.24 0 -0.094" rpy="0 0 0"/>
</joint>

<link name="rear_wheel_link">
  <visual>
    <geometry>
      <sphere radius="0.009"/>
    </geometry>
    <origin xyz="0 0 0" rpy="0 0 0"/>
    <material name="blue"/>
  </visual>
  <collision>
    <geometry>
      <sphere radius="0.001"/>
    </geometry>
    <origin xyz="0 0 0" rpy="1.0 0 0"/>
  </collision>
  <inertial>
      <origin xyz="0 0 0" rpy="0 0 0"/>
      <mass value="0.01"/>
      <inertia
        ixx="0.01" ixy="0.0" ixz="0.0"
        iyy="0.01" iyz="0.0"
        izz="0.01"/>
    </inertial>
</link>

<joint name="base_to_rear_wheel" type="fixed">
  <parent link="base_link"/>
  <child link="rear_wheel_link"/>
  <origin xyz="-0.24 0 -0.094" rpy="0 0 0"/>
</joint>

<!-- Add the differential_drive_controller -->
<gazebo>
  <plugin name="differential_drive_controller" filename="libgazebo_ros_diff_drive.so">
      <rosDebugLevel>Info</rosDebugLevel>
      <publishWheelTF>false</publishWheelTF>
      <publishWheelJointState>true</publishWheelJointState>
      <alwaysOn>true</alwaysOn>
      <leftJoint>base_to_left_wheel</leftJoint>
      <rightJoint>base_to_right_wheel</rightJoint>
      <wheelSeparation>0.569</wheelSeparation>
      <wheelDiameter>0.1</wheelDiameter>
      <wheelTorque>20</wheelTorque>
      <wheelAcceleration>1.8</wheelAcceleration>
      <commandTopic>cmd_vel</commandTopic>
      <odometryTopic>odom</odometryTopic>
      <odometryFrame>odom</odometryFrame>
      <odometrySource>world</odometrySource>
      <robotBaseFrame>base_link</robotBaseFrame>
      <updateRate>10.0</updateRate>
  </plugin>
</gazebo>

<gazebo>
    <plugin filename="libgazebo_ros_joint_state_publisher.so" name="joint_state_publisher">
      <jointName>base_to_left_wheel, base_to_right_wheel</jointName>
      <updateRate>20.0</updateRate>
      <alwaysOn>true</alwaysOn>
    </plugin>
</gazebo>

</robot>
